Workbook

Sheet Summary
A1: Okta to PingFederate SAML Migration Report
A3: Customer | B3: Customer
A4: Generated (UTC) | B4: 2026-09-27 16:17
A5: Risk rules version | B5: 2026.09-pf-2
A6: Target | B6: PingFederate (self-hosted)
A7: Directory | B7: AD
A8: OGNL allowed | B8: No
A9: PingFederate base URL (assumed) | B9: https://sso.example.com
A10: PingFederate entity ID (assumed) | B10: https://sso.example.com
C11: Base URL and entity ID come from PF_BASE_URL / PF_ENTITY_ID in .env
A13: Applications | B13: SAML | C13: OIDC
A14: Applications | B14: =COUNTIF(Applications!$C$2:$C$12,"SAML") | C14: =COUNTIF(Applications!$C$2:$C$12,"OIDC")
A15: Blocked | B15: =COUNTIFS(Applications!$C$2:$C$12,"SAML",Applications!$P$2:$P$12,"Yes") | C15: =COUNTIFS(Applications!$C$2:$C$12,"OIDC",Applications!$P$2:$P$12,"Yes")
A16: Need access control (issuance criteria / policy) | B16: =COUNTIFS(Applications!$C$2:$C$12,"SAML",Applications!$W$2:$W$12,"Yes") | C16: =COUNTIFS(Applications!$C$2:$C$12,"OIDC",Applications!$W$2:$W$12,"Yes")
A17: Total assigned users | B17: =SUMIF(Applications!$C$2:$C$12,"SAML",Applications!$G$2:$G$12) | C17: =SUMIF(Applications!$C$2:$C$12,"OIDC",Applications!$G$2:$G$12)
A19: Overall level | B19: SAML | C19: OIDC
A20: LOW | B20: =COUNTIFS(Applications!$C$2:$C$12,"SAML",Applications!$O$2:$O$12,"LOW") | C20: =COUNTIFS(Applications!$C$2:$C$12,"OIDC",Applications!$O$2:$O$12,"LOW")
A21: MEDIUM | B21: =COUNTIFS(Applications!$C$2:$C$12,"SAML",Applications!$O$2:$O$12,"MEDIUM") | C21: =COUNTIFS(Applications!$C$2:$C$12,"OIDC",Applications!$O$2:$O$12,"MEDIUM")
A22: HIGH | B22: =COUNTIFS(Applications!$C$2:$C$12,"SAML",Applications!$O$2:$O$12,"HIGH") | C22: =COUNTIFS(Applications!$C$2:$C$12,"OIDC",Applications!$O$2:$O$12,"HIGH")
A23: CRITICAL | B23: =COUNTIFS(Applications!$C$2:$C$12,"SAML",Applications!$O$2:$O$12,"CRITICAL") | C23: =COUNTIFS(Applications!$C$2:$C$12,"OIDC",Applications!$O$2:$O$12,"CRITICAL")
A25: Suggested wave | B25: SAML | C25: OIDC
A26: Wave 0 (pilot) | B26: =COUNTIFS(Applications!$C$2:$C$12,"SAML",Applications!$R$2:$R$12,"Wave 0 (pilot)") | C26: =COUNTIFS(Applications!$C$2:$C$12,"OIDC",Applications!$R$2:$R$12,"Wave 0 (pilot)")
A27: Wave 1 | B27: =COUNTIFS(Applications!$C$2:$C$12,"SAML",Applications!$R$2:$R$12,"Wave 1") | C27: =COUNTIFS(Applications!$C$2:$C$12,"OIDC",Applications!$R$2:$R$12,"Wave 1")
A28: Wave 2 | B28: =COUNTIFS(Applications!$C$2:$C$12,"SAML",Applications!$R$2:$R$12,"Wave 2") | C28: =COUNTIFS(Applications!$C$2:$C$12,"OIDC",Applications!$R$2:$R$12,"Wave 2")
A29: Wave 3 (high impact) | B29: =COUNTIFS(Applications!$C$2:$C$12,"SAML",Applications!$R$2:$R$12,"Wave 3 (high impact)") | C29: =COUNTIFS(Applications!$C$2:$C$12,"OIDC",Applications!$R$2:$R$12,"Wave 3 (high impact)")
A30: Blocked | B30: =COUNTIFS(Applications!$C$2:$C$12,"SAML",Applications!$R$2:$R$12,"Blocked") | C30: =COUNTIFS(Applications!$C$2:$C$12,"OIDC",Applications!$R$2:$R$12,"Blocked")
A31: Decommission review | B31: =COUNTIFS(Applications!$C$2:$C$12,"SAML",Applications!$R$2:$R$12,"Decommission review") | C31: =COUNTIFS(Applications!$C$2:$C$12,"OIDC",Applications!$R$2:$R$12,"Decommission review")
A33: PingFederate build status | B33: SAML | C33: OIDC
A34: Blocked | B34: =COUNTIFS(Applications!$C$2:$C$12,"SAML",Applications!$AH$2:$AH$12,"Blocked") | C34: =COUNTIFS(Applications!$C$2:$C$12,"OIDC",Applications!$AH$2:$AH$12,"Blocked")
A35: Ready to build | B35: =COUNTIFS(Applications!$C$2:$C$12,"SAML",Applications!$AH$2:$AH$12,"Ready to build") | C35: =COUNTIFS(Applications!$C$2:$C$12,"OIDC",Applications!$AH$2:$AH$12,"Ready to build")
A36: Built - differs | B36: =COUNTIFS(Applications!$C$2:$C$12,"SAML",Applications!$AH$2:$AH$12,"Built - differs") | C36: =COUNTIFS(Applications!$C$2:$C$12,"OIDC",Applications!$AH$2:$AH$12,"Built - differs")
A37: Built | B37: =COUNTIFS(Applications!$C$2:$C$12,"SAML",Applications!$AH$2:$AH$12,"Built") | C37: =COUNTIFS(Applications!$C$2:$C$12,"OIDC",Applications!$AH$2:$AH$12,"Built")
A38: Verified | B38: =COUNTIFS(Applications!$C$2:$C$12,"SAML",Applications!$AH$2:$AH$12,"Verified") | C38: =COUNTIFS(Applications!$C$2:$C$12,"OIDC",Applications!$AH$2:$AH$12,"Verified")
A39: Out of scope | B39: =COUNTIFS(Applications!$C$2:$C$12,"SAML",Applications!$AH$2:$AH$12,"Out of scope") | C39: =COUNTIFS(Applications!$C$2:$C$12,"OIDC",Applications!$AH$2:$AH$12,"Out of scope")
A41: Migration plan steps | B41: SAML | C41: OIDC
A42: Not Started | B42: =COUNTIFS('Migration plan'!$B$2:$B$78,"SAML",'Migration plan'!$F$2:$F$78,"Not Started") | C42: =COUNTIFS('Migration plan'!$B$2:$B$78,"OIDC",'Migration plan'!$F$2:$F$78,"Not Started")
A43: In Progress | B43: =COUNTIFS('Migration plan'!$B$2:$B$78,"SAML",'Migration plan'!$F$2:$F$78,"In Progress") | C43: =COUNTIFS('Migration plan'!$B$2:$B$78,"OIDC",'Migration plan'!$F$2:$F$78,"In Progress")
A44: Done | B44: =COUNTIFS('Migration plan'!$B$2:$B$78,"SAML",'Migration plan'!$F$2:$F$78,"Done") | C44: =COUNTIFS('Migration plan'!$B$2:$B$78,"OIDC",'Migration plan'!$F$2:$F$78,"Done")
A45: Blocked | B45: =COUNTIFS('Migration plan'!$B$2:$B$78,"SAML",'Migration plan'!$F$2:$F$78,"Blocked") | C45: =COUNTIFS('Migration plan'!$B$2:$B$78,"OIDC",'Migration plan'!$F$2:$F$78,"Blocked")
A46: N/A | B46: =COUNTIFS('Migration plan'!$B$2:$B$78,"SAML",'Migration plan'!$F$2:$F$78,"N/A") | C46: =COUNTIFS('Migration plan'!$B$2:$B$78,"OIDC",'Migration plan'!$F$2:$F$78,"N/A")
...

Sheet Applications
A1: Okta app ID | B1: Application | C1: Protocol | D1: Type | E1: Okta status | F1: Migration state | G1: Users | H1: Direct users | I1: Groups | J1: Claims | K1: Complexity score | L1: Complexity | M1: Impact score | N1: Impact | O1: Overall | P1: Blocked | Q1: Blockers | R1: Suggested wave | S1: Assigned wave | T1: Business owner | U1: Criticality | V1: Test env | W1: Issuance criteria needed | X1: OGNL values | Y1: Okta-only groups | Z1: LDAP attributes | AA1: Missing directory inputs | AB1: Critical | AC1: Warning | AD1: Info | AE1: Assessment | AF1: Assessment review | AG1: Reviewed by | AH1: PingFederate build | AI1: Plan steps done | AJ1: Next plan step
A2: 0oa7employeeportal7 | B2: Employee Portal | C2: OIDC | D2: Web | E2: ACTIVE | F2: DISCOVERED | G2: 25 | H2: 0 | I2: 1 | J2: 0 | K2: 6 | L2: MEDIUM | M2: 5 | N2: MEDIUM | O2: MEDIUM | P2: No | Q2: ' | R2: Wave 1 | S2: ' | T2: ' | U2: ' | V2: Unknown | W2: Yes | X2: ' | Y2: ' | Z2: ' | AA2: ' | AB2: 0 | AC2: 2 | AD2: 4 | AE2: Not run | AF2: ' | AG2: ' | AH2: Built - differs | AI2: 0/7 | AJ2: Prepare directory & decisions
A3: 0oa3engwiki00000003 | B3: Engineering Wiki (Confluence DC) | C3: SAML | D3: Custom | E3: ACTIVE | F3: DISCOVERED | G3: 10 | H3: 0 | I3: 3 | J3: 4 | K3: 20 | L3: CRITICAL | M3: 5 | N3: MEDIUM | O3: CRITICAL | P3: Yes | Q3: CLAIM_NEEDS_OGNL | R3: Blocked | S3: ' | T3: ' | U3: ' | V3: Unknown | W3: Yes | X3: fullName, wikiRole | Y3: ENG-Contractors | Z3: cn, department, givenName, mail, sn, userPrincipalName | AA3: ' | AB3: 2 | AC3: 5 | AD3: 6 | AE3: VALID | AF3: PENDING | AG3: ' | AH3: Built - differs | AI3: 0/7 | AJ3: Prepare directory & decisions
A4: 0oa1expenseportal01 | B4: Expense Portal | C4: SAML | D4: Custom | E4: ACTIVE | F4: DISCOVERED | G4: 25 | H4: 0 | I4: 1 | J4: 1 | K4: 4 | L4: LOW | M4: 5 | N4: MEDIUM | O4: MEDIUM | P4: Yes | Q4: DUPLICATE_SP_ENTITY_ID | R4: Blocked | S4: ' | T4: ' | U4: ' | V4: Unknown | W4: Yes | X4: ' | Y4: ' | Z4: mail | AA4: ' | AB4: 0 | AC4: 2 | AD4: 2 | AE4: VALID | AF4: PENDING | AG4: ' | AH4: Built | AI4: 0/7 | AJ4: Prepare directory & decisions
A5: 0oa1expenseuat00011 | B5: Expense Portal (UAT) | C5: SAML | D5: Custom | E5: ACTIVE | F5: DISCOVERED | G5: 5 | H5: 0 | I5: 1 | J5: 1 | K5: 6 | L5: MEDIUM | M5: 4 | N5: MEDIUM | O5: MEDIUM | P5: Yes | Q5: DUPLICATE_SP_ENTITY_ID | R5: Decommission review | S5: ' | T5: ' | U5: ' | V5: Unknown | W5: Yes | X5: ' | Y5: Finance | Z5: mail | AA5: ' | AB5: 0 | AC5: 4 | AD5: 1 | AE5: VALID | AF5: PENDING | AG5: ' | AH5: Built - differs | AI5: 0/7 | AJ5: Prepare directory & decisions
A6: 0oa2hranalytics0002 | B6: HR Analytics (Tableau) | C6: SAML | D6: Custom | E6: ACTIVE | F6: DISCOVERED | G6: 5 | H6: 2 | I6: 1 | J6: 7 | K6: 15 | L6: HIGH | M6: 5 | N6: MEDIUM | O6: HIGH | P6: Yes | Q6: CLAIM_NEEDS_OGNL | R6: Blocked | S6: ' | T6: ' | U6: ' | V6: Unknown | W6: Yes | X6: displayName, username | Y6: HR-Analysts | Z6: employeeID, givenName, mail, sn, userPrincipalName | AA6: appuser.costCenter | AB6: 2 | AC6: 6 | AD6: 1 | AE6: VALID | AF6: PENDING | AG6: ' | AH6: Blocked | AI6: 0/7 | AJ6: Prepare directory & decisions
A7: 0oa10legacyspa00010 | B7: Legacy Intranet SPA | C7: OIDC | D7: Browser | E7: ACTIVE | F7: DISCOVERED | G7: 9 | H7: 1 | I7: 1 | J7: 0 | K7: 11 | L7: HIGH | M7: 4 | N7: MEDIUM | O7: HIGH | P7: No | Q7: ' | R7: Decommission review | S7: ' | T7: ' | U7: ' | V7: Unknown | W7: Yes | X7: ' | Y7: Sales | Z7: ' | AA7: ' | AB7: 0 | AC7: 6 | AD7: 2 | AE7: Not run | AF7: ' | AG7: ' | AH7: Ready to build | AI7: 0/7 | AJ7: Prepare directory & decisions
A8: 0oa6legacytravel006 | B8: Legacy Travel Booking | C8: SAML | D8: Custom | E8: INACTIVE | F8: DISCOVERED | G8: 0 | H8: 0 | I8: 0 | J8: 1 | K8: 5 | L8: MEDIUM | M8: 0 | N8: LOW | O8: MEDIUM | P8: Yes | Q8: NAMEID_IS_OKTA_USER_ID | R8: Decommission review | S8: ' | T8: ' | U8: ' | V8: Unknown | W8: No | X8: ' | Y8: ' | Z8: mail | AA8: user.id | AB8: 2 | AC8: 1 | AD8: 3 | AE8: VALID | AF8: PENDING | AG8: ' | AH8: Blocked | AI8: 0/7 | AJ8: Prepare directory & decisions
A9: 0oa8mobileexpense08 | B9: Mobile Expenses | C9: OIDC | D9: Native | E9: ACTIVE | F9: DISCOVERED | G9: 5 | H9: 0 | I9: 1 | J9: 0 | K9: 6 | L9: MEDIUM | M9: 5 | N9: MEDIUM | O9: MEDIUM | P9: No | Q9: ' | R9: Wave 1 | S9: ' | T9: ' | U9: ' | V9: Unknown | W9: Yes | X9: ' | Y9: Finance | Z9: ' | AA9: ' | AB9: 0 | AC9: 2 | AD9: 3 | AE9: Not run | AF9: ' | AG9: ' | AH9: Ready to build | AI9: 0/7 | AJ9: Prepare directory & decisions
A10: 0oa9reportingapi009 | B10: Reporting API | C10: OIDC | D10: Service | E10: ACTIVE | F10: DISCOVERED | G10: 0 | H10: 0 | I10: 0 | J10: 0 | K10: 2 | L10: LOW | M10: 4 | N10: MEDIUM | O10: MEDIUM | P10: No | Q10: ' | R10: Wave 1 | S10: ' | T10: ' | U10: ' | V10: Unknown | W10: No | X10: ' | Y10: ' | Z10: ' | AA10: ' | AB10: 0 | AC10: 0 | AD10: 4 | AE10: Not run | AF10: ' | AG10: ' | AH10: Built | AI10: 0/7 | AJ10: Prepare directory & decisions
A11: 0oa5salesforce00005 | B11: Salesforce | C11: SAML | D11: Catalog | E11: ACTIVE | F11: DISCOVERED | G11: 8 | H11: 0 | I11: 1 | J11: 0 | K11: 10 | L11: HIGH | M11: 5 | N11: MEDIUM | O11: HIGH | P11: No | Q11: ' | R11: Wave 2 | S11: ' | T11: ' | U11: ' | V11: Unknown | W11: Yes | X11: ' | Y11: Sales | Z11: ' | AA11: ' | AB11: 0 | AC11: 4 | AD11: 0 | AE11: VALID | AF11: PENDING | AG11: ' | AH11: Ready to build | AI11: 0/7 | AJ11: Prepare directory & decisions
A12: 0oa4servicenow00004 | B12: ServiceNow | C12: SAML | D12: Catalog | E12: ACTIVE | F12: DISCOVERED | G12: 12 | H12: 0 | I12: 2 | J12: 0 | K12: 8 | L12: MEDIUM | M12: 5 | N12: MEDIUM | O12: MEDIUM | P12: No | Q12: ' | R12: Wave 1 | S12: ' | T12: ' | U12: ' | V12: Unknown | W12: Yes | X12: ' | Y12: SN-Approvers, SN-ITIL | Z12: ' | AA12: ' | AB12: 0 | AC12: 3 | AD12: 0 | AE12: VALID | AF12: PENDING | AG12: ' | AH12: Built | AI12: 0/7 | AJ12: Prepare directory & decisions

Sheet SAML - Okta vs PingFederate
A1: Application | B1: Section | C1: Field | D1: Okta value | E1: PingFederate setting | F1: PingFederate value | G1: Status | H1: Note
A2: Engineering Wiki (Confluence DC) | B2: SP connection | C2: Connection name | D2: Engineering Wiki (Confluence DC) | E2: SP Connection > General Info > Connection Name | F2: Engineering Wiki (Confluence DC) | G2: CONFIGURE | H2: '
A3: Engineering Wiki (Confluence DC) | B3: SP connection | C3: SP entity ID | D3: https://wiki.northwind.example | E3: Partner's Entity ID (Connection ID) | F3: https://wiki.northwind.example | G3: SAME | H3: '
A4: Engineering Wiki (Confluence DC) | B4: SP connection | C4: Okta app status | D4: ACTIVE | E4: Connection status | F4: Active | G4: SAME | H4: '
A5: Engineering Wiki (Confluence DC) | B5: SP connection | C5: ACS URL (index 0) | D5: https://wiki.northwind.example/plugins/servlet/samlconsumer | E5: Protocol Settings > Assertion Consumer Service URL (HTTP-POST) | F5: https://wiki.northwind.example/plugins/servlet/samlconsumer | G5: SAME | H5: Set 'Default' on index 0
A6: Engineering Wiki (Confluence DC) | B6: SP connection | C6: ACS URL (index 1) | D6: https://wiki-dr.northwind.example/plugins/servlet/samlconsumer | E6: Protocol Settings > Assertion Consumer Service URL (HTTP-POST) | F6: https://wiki-dr.northwind.example/plugins/servlet/samlconsumer | G6: SAME | H6: '
A7: Engineering Wiki (Confluence DC) | B7: SP connection | C7: Default RelayState | D7: https://wiki.northwind.example/dashboard.action | E7: IdP-initiated SSO TargetResource | F7: https://wiki.northwind.example/dashboard.action | G7: SAME | H7: '
A8: Engineering Wiki (Confluence DC) | B8: SP connection | C8: Single logout | D8: Yes (https://wiki.northwind.example/plugins/servlet/samlslo) | E8: Protocol Settings > SLO Service URL | F8: https://wiki.northwind.example/plugins/servlet/samlslo | G8: CONFIGURE | H8: '
A9: Engineering Wiki (Confluence DC) | B9: SP connection | C9: Signed AuthnRequests | D9: Yes | E9: Signature Verification > require signed AuthnRequests + SP certificate | F9: Import SP signing certificate | G9: CONFIGURE | H9: '
A10: Engineering Wiki (Confluence DC) | B10: IdP identity | C10: IdP entity ID (Issuer) | D10: https://sso.northwind.example/wiki | E10: Virtual Server ID on the connection | F10: https://sso.northwind.example/wiki | G10: ACTION | H10: Add the custom issuer as a virtual server ID so the SP needs no change
A11: Engineering Wiki (Confluence DC) | B11: IdP identity | C11: SSO URL | D11: https://northwind.okta.com/app/northwind_engwiki_1/exk3engwiki00000003/sso/saml | E11: Runtime SSO endpoint | F11: https://sso.example.com/idp/SSO.saml2 | G11: SP_UPDATE | H11: '
A12: Engineering Wiki (Confluence DC) | B12: IdP identity | C12: IdP-initiated SSO link | D12: Okta app embed link | E12: IdP-initiated SSO URL | F12: https://sso.example.com/idp/startSSO.ping?PartnerSpId=https%3A%2F%2Fwiki.northwind.example | G12: SP_UPDATE | H12: Update portal bookmarks and links
... A160: ServiceNow | B160: Access control | C160: Okta-only groups | D160: SN-ITIL, SN-Approvers | E160: Directory groups | F160: Create and populate in the directory | G160: ACTION | H160: '

Sheet OIDC - Okta vs PingFederate
A1: Application | B1: Section | C1: Field | D1: Okta value | E1: PingFederate setting | F1: PingFederate value | G1: Status | H1: Note
A2: Employee Portal | B2: OAuth client | C2: Client name | D2: Employee Portal | E2: OAuth Client > Name | F2: Employee Portal | G2: CONFIGURE | H2: '
A3: Employee Portal | B3: OAuth client | C3: Client ID | D3: 0oa7EmpPortalClient01 | E3: OAuth Client > Client ID | F3: 0oa7EmpPortalClient01 | G3: SAME | H3: PingFederate lets you keep the same client ID, so the app config for it does not change
A4: Employee Portal | B4: OAuth client | C4: Application type | D4: web | E4: Client type (derived) | F4: Confidential client (web app) | G4: CONFIGURE | H4: '
A5: Employee Portal | B5: OAuth client | C5: Client authentication | D5: client_secret_basic | E5: Client Authentication | F5: Client Secret (HTTP Basic) - new secret | G5: ACTION | H5: Okta does not return existing secrets; issue a new one and update the app
A6: Employee Portal | B6: OAuth client | C6: Okta app status | D6: ACTIVE | E6: Client status | F6: Enabled | G6: SAME | H6: '
A7: Employee Portal | B7: OAuth client | C7: Consent | D7: TRUSTED | E7: Bypass Authorization Approval | F7: Bypass (trusted) | G7: SAME | H7: '
A8: Employee Portal | B8: Redirects | C8: Redirect URI 1 | D8: https://portal.northwind.example/callback | E8: Redirect URIs | F8: https://portal.northwind.example/callback | G8: SAME | H8: '
A9: Employee Portal | B9: Redirects | C9: Redirect URI 2 | D9: https://portal.northwind.example/silent-renew | E9: Redirect URIs | F9: https://portal.northwind.example/silent-renew | G9: SAME | H9: '
A10: Employee Portal | B10: Redirects | C10: Post-logout redirect 1 | D10: https://portal.northwind.example/ | E10: Logout URIs | F10: https://portal.northwind.example/ | G10: SAME | H10: '
A11: Employee Portal | B11: Redirects | C11: Initiate login URI | D11: https://portal.northwind.example/login | E11: Portal / launcher link | F11: https://portal.northwind.example/login | G11: CONFIGURE | H11: Use in your app launcher; PingFederate does not start OIDC logins itself
A12: Employee Portal | B12: Grants & tokens | C12: Grant: authorization_code | D12: authorization_code | E12: Allowed Grant Types | F12: Authorization Code | G12: SAME | H12: '
... A92: Reporting API | B92: Access control | C92: Who can use it | D92: Machine client (no users) | E92: Client credentials only | F92: Restrict by client and scopes | G92: CONFIGURE | H92: '

Sheet PingFederate reconciliation
A1: Okta app | B1: Protocol | C1: PingFederate object | D1: Matched by | E1: Check | F1: Expected (Okta) | G1: Actual (PingFederate) | H1: Result
A2: Employee Portal | B2: OIDC | C2: Employee Portal | D2: client ID | E2: Redirect URIs | F2: https://portal.northwind.example/callback, https://portal.northwind.example/silent-renew | G2: https://portal.northwind.example/callback | H2: DIFFERS
A3: Employee Portal | B3: OIDC | C3: Employee Portal | D3: client ID | E3: Grant types | F3: authorization_code, refresh_token | G3: authorization_code, refresh_token | H3: OK
A4: Employee Portal | B4: OIDC | C4: Employee Portal | D4: client ID | E4: Client authentication | F4: client_secret | G4: client_secret | H4: OK
A5: Employee Portal | B5: OIDC | C5: Employee Portal | D5: client ID | E5: Access control | F5: Authentication policy / issuance criteria | G5: Verify in PingFederate policies (not on the client) | H5: OK
A6: Engineering Wiki (Confluence DC) | B6: SAML | C6: Engineering Wiki (Confluence DC) | D6: entity ID | E6: ACS URLs | F6: https://wiki-dr.northwind.example/plugins/servlet/samlconsumer, https://wiki.northwind.example/plugins/servlet/samlconsumer | G6: https://wiki.northwind.example/plugins/servlet/samlconsumer | H6: DIFFERS
A7: Engineering Wiki (Confluence DC) | B7: SAML | C7: Engineering Wiki (Confluence DC) | D7: entity ID | E7: Attribute contract | F7: SAML_SUBJECT, email, fullName, groups, wikiRole | G7: SAML_SUBJECT, email, fullName, groups (missing: wikiRole) | H7: DIFFERS
A8: Engineering Wiki (Confluence DC) | B8: SAML | C8: Engineering Wiki (Confluence DC) | D8: entity ID | E8: Sign assertion | F8: Yes | G8: Yes | H8: OK
A9: Engineering Wiki (Confluence DC) | B9: SAML | C9: Engineering Wiki (Confluence DC) | D9: entity ID | E9: Virtual server ID | F9: https://sso.northwind.example/wiki | G9: — | H9: DIFFERS
A10: Engineering Wiki (Confluence DC) | B10: SAML | C10: Engineering Wiki (Confluence DC) | D10: entity ID | E10: Issuance criteria (access control) | F10: Required | G10: None | H10: DIFFERS
A11: Engineering Wiki (Confluence DC) | B11: SAML | C11: Engineering Wiki (Confluence DC) | D11: entity ID | E11: Single logout | F11: https://wiki.northwind.example/plugins/servlet/samlslo | G11: — | H11: DIFFERS
A12: Expense Portal | B12: SAML | C12: Expense Portal | D12: entity ID | E12: ACS URLs | F12: https://expenses.northwind.example/saml/acs | G12: https://expenses.northwind.example/saml/acs | H12: OK
... A26: ServiceNow | B26: SAML | C26: ServiceNow | D26: name | E26: Issuance criteria (access control) | F26: Required | G26: Present | H26: OK

Sheet Migration plan
A1: Application | B1: Protocol | C1: Wave | D1: # | E1: Step | F1: Status | G1: Owner | H1: Due date | I1: Notes | J1: Updated by | K1: PingFederate build
A2: Employee Portal | B2: OIDC | C2: Wave 1 | D2: 1 | E2: Prepare directory & decisions | F2: Not Started | G2: Directory team | I2: ' | J2: ' | K2: Built - differs
A3: Employee Portal | B3: OIDC | C3: Wave 1 | D3: 2 | E3: Build in PingFederate | F3: Not Started | G3: IAM team | I3: ' | J3: ' | K3: Built - differs
A4: Employee Portal | B4: OIDC | C4: Wave 1 | D4: 3 | E4: Test with pilot users | F4: Not Started | G4: IAM team | I4: ' | J4: ' | K4: Built - differs
A5: Employee Portal | B5: OIDC | C5: Wave 1 | D5: 4 | E5: Update the SP / app | F5: Not Started | G5: App owner | I5: ' | J5: ' | K5: Built - differs
A6: Employee Portal | B6: OIDC | C6: Wave 1 | D6: 5 | E6: Cutover | F6: Not Started | G6: IAM team + App owner | I6: ' | J6: ' | K6: Built - differs
A7: Employee Portal | B7: OIDC | C7: Wave 1 | D7: 6 | E7: Verify | F7: Not Started | G7: App owner | I7: ' | J7: ' | K7: Built - differs
A8: Employee Portal | B8: OIDC | C8: Wave 1 | D8: 7 | E8: Remove from Okta | F8: Not Started | G8: IAM team | I8: ' | J8: ' | K8: Built - differs
A9: Engineering Wiki (Confluence DC) | B9: SAML | C9: Blocked | D9: 1 | E9: Prepare directory & decisions | F9: Not Started | G9: Directory team | I9: ' | J9: ' | K9: Built - differs
A10: Engineering Wiki (Confluence DC) | B10: SAML | C10: Blocked | D10: 2 | E10: Build in PingFederate | F10: Not Started | G10: IAM team | I10: ' | J10: ' | K10: Built - differs
A11: Engineering Wiki (Confluence DC) | B11: SAML | C11: Blocked | D11: 3 | E11: Test with pilot users | F11: Not Started | G11: IAM team | I11: ' | J11: ' | K11: Built - differs
A12: Engineering Wiki (Confluence DC) | B12: SAML | C12: Blocked | D12: 4 | E12: Update the SP / app | F12: Not Started | G12: App owner | I12: ' | J12: ' | K12: Built - differs
A13: Engineering Wiki (Confluence DC) | B13: SAML | C13: Blocked | D13: 5 | E13: Cutover | F13: Not Started | G13: IAM team + App owner | I13: ' | J13: ' | K13: Built - differs
... A78: ServiceNow | B78: SAML | C78: Wave 1 | D78: 7 | E78: Remove from Okta | F78: Not Started | G78: IAM team | I78: ' | J78: ' | K78: Built

Sheet Attribute mapping
A1: Application | B1: Attribute | C1: Type | D1: Okta value / filter | E1: Okta classification | F1: PingFederate source | G1: PingFederate detail | H1: LDAP attributes | I1: Missing inputs | J1: Okta-only groups
A2: Engineering Wiki (Confluence DC) | B2: email | C2: EXPRESSION | D2: user.email | E2: DIRECT | F2: DATA_STORE | G2: LDAP: mail | H2: mail | I2: ' | J2: '
A3: Engineering Wiki (Confluence DC) | B3: fullName | C3: EXPRESSION | D3: user.firstName + " " + user.lastName | E3: COMPLEX | F3: OGNL | G3: OGNL needed (<concatenation>); LDAP inputs: givenName, sn | H3: givenName, sn | I3: ' | J3: '
A4: Engineering Wiki (Confluence DC) | B4: wikiRole | C4: EXPRESSION | D4: user.department == "Engineering" ? "wiki-admin" : "wiki-user" | E4: COMPLEX | F4: OGNL | G4: OGNL needed (<conditional>); LDAP inputs: department | H4: department | I4: ' | J4: '
A5: Engineering Wiki (Confluence DC) | B5: groups | C5: GROUP | D5: REGEX ENG-.* | E5: GROUP | F5: GROUP_LDAP_SEARCH | G5: Chained LDAP attribute source returning cn, e.g. (&(objectClass=group)(member=<user DN>)(cn=ENG-*)) | H5: cn | I5: ' | J5: ENG-Contractors
A6: Expense Portal | B6: email | C6: EXPRESSION | D6: user.email | E6: DIRECT | F6: DATA_STORE | G6: LDAP: mail | H6: mail | I6: ' | J6: '
A7: Expense Portal (UAT) | B7: email | C7: EXPRESSION | D7: user.email | E7: DIRECT | F7: DATA_STORE | G7: LDAP: mail | H7: mail | I7: ' | J7: '
A8: HR Analytics (Tableau) | B8: firstName | C8: EXPRESSION | D8: user.firstName | E8: DIRECT | F8: DATA_STORE | G8: LDAP: givenName | H8: givenName | I8: ' | J8: '
A9: HR Analytics (Tableau) | B9: lastName | C9: EXPRESSION | D9: user.lastName | E9: DIRECT | F9: DATA_STORE | G9: LDAP: sn | H9: sn | I9: ' | J9: '
A10: HR Analytics (Tableau) | B10: email | C10: EXPRESSION | D10: user.email | E10: DIRECT | F10: DATA_STORE | G10: LDAP: mail | H10: mail | I10: ' | J10: '
A11: HR Analytics (Tableau) | B11: employeeNumber | C11: EXPRESSION | D11: user.employeeNumber | E11: DIRECT | F11: DATA_STORE | G11: LDAP: employeeID | H11: employeeID | I11: ' | J11: '
A12: HR Analytics (Tableau) | B12: displayName | C12: EXPRESSION | D12: user.firstName + " " + user.lastName | E12: COMPLEX | F12: OGNL | G12: OGNL needed (<concatenation>); LDAP inputs: givenName, sn | H12: givenName, sn | I12: ' | J12: '
... A15: Legacy Travel Booking | B15: mail | C15: EXPRESSION | D15: user.email | E15: DIRECT | F15: DATA_STORE | G15: LDAP: mail | H15: mail | I15: ' | J15: '

Sheet Directory prep
A1: Item | B1: Name | C1: Apps affected | D1: Applications
A2: Group to create | B2: ENG-Contractors | C2: 1 | D2: Engineering Wiki (Confluence DC)
A3: Group to create | B3: Finance | C3: 2 | D3: Expense Portal (UAT), Mobile Expenses
A4: Group to create | B4: HR-Analysts | C4: 1 | D4: HR Analytics (Tableau)
A5: Group to create | B5: SN-Approvers | C5: 1 | D5: ServiceNow
A6: Group to create | B6: SN-ITIL | C6: 1 | D6: ServiceNow
A7: Group to create | B7: Sales | C7: 2 | D7: Legacy Intranet SPA, Salesforce
A8: LDAP attribute read | B8: cn | C8: 1 | D8: Engineering Wiki (Confluence DC)
A9: LDAP attribute read | B9: department | C9: 1 | D9: Engineering Wiki (Confluence DC)
A10: LDAP attribute read | B10: employeeID | C10: 1 | D10: HR Analytics (Tableau)
A11: LDAP attribute read | B11: givenName | C11: 2 | D11: Engineering Wiki (Confluence DC), HR Analytics (Tableau)
A12: LDAP attribute read | B12: mail | C12: 5 | D12: Engineering Wiki (Confluence DC), Expense Portal, Expense Portal (UAT), HR Analytics (Tableau), Legacy Travel Booking
A13: LDAP attribute read | B13: sn | C13: 2 | D13: Engineering Wiki (Confluence DC), HR Analytics (Tableau)
... A16: Value with no directory source | B16: user.id | C16: 1 | D16: Legacy Travel Booking

Sheet Action plan
A1: Application | B1: When | C1: Owner | D1: Action | E1: Resolves findings | F1: Source | G1: Review
A2: Engineering Wiki (Confluence DC) | B2: Before Migration | C2: Directory Team | D2: Pre-compute the expression result into a directory attribute, or get security approval for OGNL. | E2: CLAIM_NEEDS_OGNL | F2: offline (offline-rules-v1) | G2: PENDING
A3: Engineering Wiki (Confluence DC) | B3: Before Migration | C3: IAM Team | D3: Add every ACS URL to the SP connection with the same index values. | E3: MULTIPLE_ACS | F3: offline (offline-rules-v1) | G3: PENDING
A4: Engineering Wiki (Confluence DC) | B4: Before Migration | C4: IAM Team | D4: Enable 'Always sign the SAML assertion' on the SP connection. | E4: RESPONSE_AND_ASSERTION_SIGNED | F4: offline (offline-rules-v1) | G4: PENDING
A5: Engineering Wiki (Confluence DC) | B5: Before Migration | C5: IAM Team | D5: Import the SP signing certificate into the connection. | E5: SIGNED_AUTHN_REQUESTS | F5: offline (offline-rules-v1) | G5: PENDING
A6: Engineering Wiki (Confluence DC) | B6: Before Migration | C6: IAM Team | D6: Enable SLO on the SP connection and add the SP logout endpoint. | E6: SLO_ENABLED | F6: offline (offline-rules-v1) | G6: PENDING
A7: Engineering Wiki (Confluence DC) | B7: Before Migration | C7: Directory Team | D7: Store per-assignment values (e.g. role) in the directory or derive them from group membership. | E7: ASSIGNMENT_PROFILE_ATTRIBUTES | F7: offline (offline-rules-v1) | G7: PENDING
A8: Engineering Wiki (Confluence DC) | B8: Before Migration | C8: IAM Team | D8: Set a virtual server ID matching the current issuer on the SP connection. | E8: CUSTOM_IDP_ISSUER | F8: offline (offline-rules-v1) | G8: PENDING
A9: Engineering Wiki (Confluence DC) | B9: Before Migration | C9: IAM Team | D9: Configure a chained LDAP attribute source for group names and fulfil the group attribute from it. | E9: GROUP_CLAIM | F9: offline (offline-rules-v1) | G9: PENDING
A10: Engineering Wiki (Confluence DC) | B10: Before Migration | C10: App Owner | D10: Decide whether the Okta-only groups in the group claim must be created in the directory. | E10: GROUP_CLAIM_OKTA_NATIVE_GROUPS | F10: offline (offline-rules-v1) | G10: PENDING
A11: Engineering Wiki (Confluence DC) | B11: Before Migration | C11: IAM Team | D11: Add issuance criteria on the SP connection restricting access to the assigned groups (memberOf). | E11: ISSUANCE_CRITERIA_REQUIRED | F11: offline (offline-rules-v1) | G11: PENDING
A12: Engineering Wiki (Confluence DC) | B12: During Cutover | C12: Vendor | D12: Give the SP the PingFederate metadata (entity ID, SSO URL, signing certificate) at cutover. | E12: ' | F12: offline (offline-rules-v1) | G12: PENDING
... A52: ServiceNow | B52: After Cutover | C52: IAM Team | D52: Test sign-in with pilot users, compare the assertion with Okta's, then remove the Okta app. | E52: ' | F52: offline (offline-rules-v1) | G52: PENDING

Sheet Owner questions
A1: Application | B1: Business owner | C1: Question | D1: Answer (fill in)
A2: Engineering Wiki (Confluence DC) | B2: Unknown | C2: Who is the business owner for this application? | D2: '
A3: Engineering Wiki (Confluence DC) | B3: Unknown | C3: How critical is this application to the business (low / medium / high)? | D3: '
A4: Engineering Wiki (Confluence DC) | B4: Unknown | C4: Does the vendor provide a test or sandbox instance we can federate first? | D4: '
A5: Engineering Wiki (Confluence DC) | B5: Unknown | C5: Does the application need nested group membership or only direct groups? | D5: '
A6: Expense Portal | B6: Unknown | C6: Who is the business owner for this application? | D6: '
A7: Expense Portal | B7: Unknown | C7: How critical is this application to the business (low / medium / high)? | D7: '
A8: Expense Portal | B8: Unknown | C8: Does the vendor provide a test or sandbox instance we can federate first? | D8: '
A9: Expense Portal | B9: Unknown | C9: Can the non-production instance use a different SP entity ID? | D9: '
A10: Expense Portal (UAT) | B10: Unknown | C10: Who is the business owner for this application? | D10: '
A11: Expense Portal (UAT) | B11: Unknown | C11: How critical is this application to the business (low / medium / high)? | D11: '
A12: Expense Portal (UAT) | B12: Unknown | C12: Does the vendor provide a test or sandbox instance we can federate first? | D12: '
... A27: ServiceNow | B27: Unknown | C27: Can you provide the SP SAML metadata or the vendor's SSO configuration page? | D27: '

Sheet Findings
A1: Application | B1: Severity | C1: Code | D1: Message
A2: Employee Portal | B2: WARNING | C2: OIDC_ACCESS_CONTROL_REQUIRED | D2: Okta only issues tokens to assigned users. In PingFederate, restrict this OAuth client with an authentication policy or issuance criteria on group membership, otherwise any user who can sign in gets tokens.
A3: Employee Portal | B3: WARNING | C3: OIDC_NEW_CLIENT_SECRET | D3: Confidential client using a shared secret. Okta does not hand back existing secrets, so plan a new secret in PingFederate and a coordinated update in the app.
A4: Employee Portal | B4: INFO | C4: DIRECTORY_SOURCED_GROUPS_ASSIGNED | D4: 1 assigned group(s) come from the directory, so PingFederate can check them through its LDAP data store.
A5: Employee Portal | B5: INFO | C5: OIDC_ISSUER_CHANGE | D5: Tokens will be issued by PingFederate, so the issuer, discovery URL and JWKS change. The app must point at PingFederate's /.well-known/openid-configuration at cutover.
A6: Employee Portal | B6: INFO | C6: OIDC_REFRESH_TOKENS | D6: The app uses refresh tokens. Okta refresh tokens cannot be moved, so users sign in again once after cutover.
A7: Employee Portal | B7: INFO | C7: OIDC_SCOPES_CLAIMS_NOT_ANALYSED | D7: Scopes, custom claims and access policies live on the Okta authorization server and are not analysed yet (next sprint). Review them manually for now.
A8: Engineering Wiki (Confluence DC) | B8: CRITICAL | C8: CLAIM_NEEDS_OGNL | D8: Claim 'fullName': OGNL needed (<concatenation>); LDAP inputs: givenName, sn. OGNL is not allowed here, so the value must be pre-computed into a directory attribute.
A9: Engineering Wiki (Confluence DC) | B9: CRITICAL | C9: CLAIM_NEEDS_OGNL | D9: Claim 'wikiRole': OGNL needed (<conditional>); LDAP inputs: department. OGNL is not allowed here, so the value must be pre-computed into a directory attribute.
A10: Engineering Wiki (Confluence DC) | B10: WARNING | C10: ASSIGNMENT_PROFILE_ATTRIBUTES | D10: Assignments carry app-specific values (e.g. a role per group). PingFederate has nowhere to hold these; store them in the directory or derive them from group membership.
A11: Engineering Wiki (Confluence DC) | B11: WARNING | C11: CUSTOM_IDP_ISSUER | D11: The SP expects the custom issuer 'https://sso.northwind.example/wiki'. Either set a matching virtual server ID on the PingFederate connection or change the issuer on the SP.
A12: Engineering Wiki (Confluence DC) | B12: WARNING | C12: GROUP_CLAIM | D12: Group claim 'groups' (REGEX 'ENG-.*') matches 4 tenant group(s). Chained LDAP attribute source returning cn, e.g. (&(objectClass=group)(member=<user DN>)(cn=ENG-*)). Check whether the SP expects nested group membership.
... A68: ServiceNow | B68: WARNING | C68: OKTA_NATIVE_GROUPS_ASSIGNED | D68: 2 assigned group(s) exist only in Okta. Create and populate them in the directory before the issuance criteria can use them.

Sheet Risk breakdown
A1: Application | B1: Dimension | C1: Rule | D1: Points | E1: Reason | F1: Rules version
A2: Employee Portal | B2: COMPLEXITY | C2: OIDC_ACCESS_CONTROL_REQUIRED | D2: 1 | E2: 1 occurrence(s) x 1 | F2: 2026.09-pf-2
A3: Employee Portal | B3: COMPLEXITY | C3: OIDC_NEW_CLIENT_SECRET | D3: 2 | E3: 1 occurrence(s) x 2 | F3: 2026.09-pf-2
A4: Employee Portal | B4: COMPLEXITY | C4: OIDC_REFRESH_TOKENS | D4: 1 | E4: 1 occurrence(s) x 1 | F4: 2026.09-pf-2
A5: Employee Portal | B5: COMPLEXITY | C5: OIDC_SCOPES_CLAIMS_NOT_ANALYSED | D5: 2 | E5: 1 occurrence(s) x 2 | F5: 2026.09-pf-2
A6: Employee Portal | B6: IMPACT | C6: ACTIVE_USERS | D6: 1 | E6: 24 active users in 90 days (25 assigned) | F6: 2026.09-pf-2
A7: Employee Portal | B7: IMPACT | C7: BUSINESS_CRITICALITY | D7: 2 | E7: Criticality not captured (assumed MEDIUM) | F7: 2026.09-pf-2
A8: Employee Portal | B8: IMPACT | C8: TEST_ENVIRONMENT | D8: 2 | E8: Test environment not captured | F8: 2026.09-pf-2
A9: Engineering Wiki (Confluence DC) | B9: COMPLEXITY | C9: ASSIGNMENT_PROFILE_ATTRIBUTES | D9: 2 | E9: 1 occurrence(s) x 2 | F9: 2026.09-pf-2
A10: Engineering Wiki (Confluence DC) | B10: COMPLEXITY | C10: CLAIM_NEEDS_OGNL | D10: 6 | E10: 2 occurrence(s) x 3 | F10: 2026.09-pf-2
A11: Engineering Wiki (Confluence DC) | B11: COMPLEXITY | C11: CUSTOM_IDP_ISSUER | D11: 2 | E11: 1 occurrence(s) x 2 | F11: 2026.09-pf-2
A12: Engineering Wiki (Confluence DC) | B12: COMPLEXITY | C12: GROUP_CLAIM | D12: 3 | E12: 1 occurrence(s) x 3 | F12: 2026.09-pf-2
A13: Engineering Wiki (Confluence DC) | B13: COMPLEXITY | C13: GROUP_CLAIM_OKTA_NATIVE_GROUPS | D13: 2 | E13: 1 occurrence(s) x 2 | F13: 2026.09-pf-2
... A75: ServiceNow | B75: IMPACT | C75: TEST_ENVIRONMENT | D75: 2 | E75: Test environment not captured | F75: 2026.09-pf-2
